Workbook

Sheet abbeygate_price_list
A1: Product ID | B1: Product Name | C1: Ancillary | D1: SKU | E1: Old SKU | F1: Sales Code? | G1: Size | H1: Colour | I1: Page Type | J1: Paper Type | K1: Corner Size | L1: Additional Corner Price | M1: Sales Price (Including VAT) | N1: Tiered Price Customisation (Qty:Price;) (Excluding VAT) | O1: Qty 1 | P1: Qty 10 | Q1: Qty 25 | R1: Qty 50 | S1: Qty 100 | T1: Qty 250 | U1: Qty 500 | V1: Qty 750 | W1: Qty 1000 | X1: Tiered Price Including UV Printing (Qty:Price;) (Excluding VAT) | Y1: Qty 1 | Z1: Qty 10 | AA1: Qty 25 | AB1: Qty 50 | AC1: Qty 100 | AD1: Qty 250 | AE1: Qty 500 | AF1: Qty 750 | AG1: Qty 1000 | AH1: 2982: B2B Users Regular Price | AI1: 2982: B2B Users Sale Price | AJ1: 2982: B2B Users Tiered Price | AK1: Notes | AL1: Short description | AM1: Description | AN1: Weight (lbs) | AO1: Length (in) | AP1: Width (in) | AQ1: Height (in) | AR1: Categories | AS1: Tags
A2: 337 | B2: Chelsea Leather A5 Notebook, Feint Ruled, Black | C2: Notebook | D2: CL-BK-U-31 | E2: CL-BK-U-31 | F2: CLU31 | G2: A5 | H2: Black | J2: White | K2: 22mm x 22mm | L2: 0.48 | M2: 16.99 | N2: 1:16.23;10:14.81;25:9.76;50:8.10;100:6.77;250:5.62;500:4.82;750:4.71;1000:4.32; | O2: =IFERROR(VALUE(_xlfn.TEXTBEFORE(_xlfn.TEXTAFTER(";"&$N2,";"&SUBSTITUTE(O$1,"Qty ","")&":"),";")),"") -> 16.23 | P2: =IFERROR(VALUE(_xlfn.TEXTBEFORE(_xlfn.TEXTAFTER(";"&$N2,";"&SUBSTITUTE(P$1,"Qty ","")&":"),";")),"") -> 14.81 | Q2: =IFERROR(VALUE(_xlfn.TEXTBEFORE(_xlfn.TEXTAFTER(";"&$N2,";"&SUBSTITUTE(Q$1,"Qty ","")&":"),";")),"") -> 9.76 | R2: =IFERROR(VALUE(_xlfn.TEXTBEFORE(_xlfn.TEXTAFTER(";"&$N2,";"&SUBSTITUTE(R$1,"Qty ","")&":"),";")),"") -> 8.1 | S2: =IFERROR(VALUE(_xlfn.TEXTBEFORE(_xlfn.TEXTAFTER(";"&$N2,";"&SUBSTITUTE(S$1,"Qty ","")&":"),";")),"") -> 6.77 | T2: =IFERROR(VALUE(_xlfn.TEXTBEFORE(_xlfn.TEXTAFTER(";"&$N2,";"&SUBSTITUTE(T$1,"Qty ","")&":"),";")),"") -> 5.62 | U2: =IFERROR(VALUE(_xlfn.TEXTBEFORE(_xlfn.TEXTAFTER(";"&$N2,";"&SUBSTITUTE(U$1,"Qty ","")&":"),";")),"") -> 4.82 | V2: =IFERROR(VALUE(_xlfn.TEXTBEFORE(_xlfn.TEXTAFTER(";"&$N2,";"&SUBSTITUTE(V$1,"Qty ","")&":"),";")),"") -> 4.71 | W2: =IFERROR(VALUE(_xlfn.TEXTBEFORE(_xlfn.TEXTAFTER(";"&$N2,";"&SUBSTITUTE(W$1,"Qty ","")&":"),";")),"") -> 4.32 | X2: {=IF(Y2="","",_xlfn.TEXTJOIN(";",TRUE,SUBSTITUTE($Y$1:$AG$1,"Qty ","")&":"&TEXT(Y2:AG2,"0.00"))&";")} -> 1:21.45;10:19.21;25:13.33;50:11.07;100:9.50;250:8.00;500:7.19;750:7.02;1000:6.57; | Y2: ='Blocking Prices'!$C$15+O2 -> 21.45 | Z2: ='Blocking Prices'!$D$15+P2 -> 19.21 | AA2: ='Blocking Prices'!$E$15+Q2 -> 13.33 | AB2: ='Blocking Prices'!$F$15+R2 -> 11.07 | AC2: ='Blocking Prices'!$G$15+S2 -> 9.5 | AD2: ='Blocking Prices'!$H$15+T2 -> 8 | AE2: ='Blocking Prices'!$I$15+U2 -> 7.19 | AF2: ='Blocking Prices'!$J$15+V2 -> 7.02 | AG2: ='Blocking Prices'!$K$15+W2 -> 6.57 | AL2: <p class="p1">Chelsea Leather range, luxury soft grained real leather?day per page layout.<span class="Apple-converted-space">?</span>Smyth sewn sections for strength and durability printed on white or cream FSC paper.<span class="Apple-converted-space">?</span>Self-colour cotton perimeter stitched flexible cover, ribbon marker, general information pages, forward planners, UK and international holidays, contacts directory, notes page and full colour map section</p>_x000D_\n&nbsp; | AM2: Chelsea Leather range, luxury soft grained real leather day per page layout. Smyth sewn sections for strength and durability printed on white or cream FSC paper. Self-colour cotton perimeter stitched flexible cover, ribbon marker, general information pages, forward planners, UK and international holidays, contacts directory, notes page and full colour map section | AN2: =IFERROR(_xlfn.LET(_xlpm.v,INDEX('product-export-27-8-2026'!$A:$AJ,MATCH($A2,'product-export-27-8-2026'!$A:$A,0),MATCH(AN$1,'product-export-27-8-2026'!$1:$1,0)),IF(_xlpm.v="","",_xlpm.v)),"") | AO2: =IFERROR(_xlfn.LET(_xlpm.v,INDEX('product-export-27-8-2026'!$A:$AJ,MATCH($A2,'product-export-27-8-2026'!$A:$A,0),MATCH(AO$1,'product-export-27-8-2026'!$1:$1,0)),IF(_xlpm.v="","",_xlpm.v)),"") | AP2: =IFERROR(_xlfn.LET(_xlpm.v,INDEX('product-export-27-8-2026'!$A:$AJ,MATCH($A2,'product-export-27-8-2026'!$A:$A,0),MATCH(AP$1,'product-export-27-8-2026'!$1:$1,0)),IF(_xlpm.v="","",_xlpm.v)),"") | AQ2: =IFERROR(_xlfn.LET(_xlpm.v,INDEX('product-export-27-8-2026'!$A:$AJ,MATCH($A2,'product-export-27-8-2026'!$A:$A,0),MATCH(AQ$1,'product-export-27-8-2026'!$1:$1,0)),IF(_xlpm.v="","",_xlpm.v)),"") | AR2: =IFERROR(_xlfn.LET(_xlpm.v,INDEX('product-export-27-8-2026'!$A:$AJ,MATCH($A2,'product-export-27-8-2026'!$A:$A,0),MATCH(AR$1,'product-export-27-8-2026'!$1:$1,0)),IF(_xlpm.v="","",_xlpm.v)),"") -> Notebooks > A5 Notebooks, Chelsea Collection, Foil blocked, Notebooks, Notebooks > Real Leather Notebooks | AS2: =IFERROR(_xlfn.LET(_xlpm.v,INDEX('product-export-27-8-2026'!$A:$AJ,MATCH($A2,'product-export-27-8-2026'!$A:$A,0),MATCH(AS$1,'product-export-27-8-2026'!$1:$1,0)),IF(_xlpm.v="","",_xlpm.v)),"") -> Chelsea-Leather-A5-Notebook-Feint-Ruled
A3: 600 | B3: Dorchester Horizon Pocket, Week to View, Black-Black | C3: Diary | D3: HZ-BK/BK-U-095 | E3: HZ-BK/BK-U-095 | F3: HZ96U | G3: Pocket | H3: Black-Black | I3: Week to View | J3: White | K3: 18mm x 18mm | L3: 0.42 | M3: 9.99 | N3: 1:9.74;10:9.33;25:5.30;50:3.77;100:3.28;250:3.07;500:2.95;750:2.77;1000:2.63; | O3: =IFERROR(VALUE(_xlfn.TEXTBEFORE(_xlfn.TEXTAFTER(";"&$N3,";"&SUBSTITUTE(O$1,"Qty ","")&":"),";")),"") -> 9.74 | P3: =IFERROR(VALUE(_xlfn.TEXTBEFORE(_xlfn.TEXTAFTER(";"&$N3,";"&SUBSTITUTE(P$1,"Qty ","")&":"),";")),"") -> 9.33 | Q3: =IFERROR(VALUE(_xlfn.TEXTBEFORE(_xlfn.TEXTAFTER(";"&$N3,";"&SUBSTITUTE(Q$1,"Qty ","")&":"),";")),"") -> 5.3 | R3: =IFERROR(VALUE(_xlfn.TEXTBEFORE(_xlfn.TEXTAFTER(";"&$N3,";"&SUBSTITUTE(R$1,"Qty ","")&":"),";")),"") -> 3.77 | S3: =IFERROR(VALUE(_xlfn.TEXTBEFORE(_xlfn.TEXTAFTER(";"&$N3,";"&SUBSTITUTE(S$1,"Qty ","")&":"),";")),"") -> 3.28 | T3: =IFERROR(VALUE(_xlfn.TEXTBEFORE(_xlfn.TEXTAFTER(";"&$N3,";"&SUBSTITUTE(T$1,"Qty ","")&":"),";")),"") -> 3.07 | U3: =IFERROR(VALUE(_xlfn.TEXTBEFORE(_xlfn.TEXTAFTER(";"&$N3,";"&SUBSTITUTE(U$1,"Qty ","")&":"),";")),"") -> 2.95 | V3: =IFERROR(VALUE(_xlfn.TEXTBEFORE(_xlfn.TEXTAFTER(";"&$N3,";"&SUBSTITUTE(V$1,"Qty ","")&":"),";")),"") -> 2.77 | W3: =IFERROR(VALUE(_xlfn.TEXTBEFORE(_xlfn.TEXTAFTER(";"&$N3,";"&SUBSTITUTE(W$1,"Qty ","")&":"),";")),"") -> 2.63 | X3: {=IF(Y3="","",_xlfn.TEXTJOIN(";",TRUE,SUBSTITUTE($Y$1:$AG$1,"Qty ","")&":"&TEXT(Y3:AG3,"0.00"))&";")} -> 1:13.16;10:11.96;25:7.13;50:5.27;100:4.66;250:4.33;500:4.15;750:3.94;1000:3.77; | Y3: ='Blocking Prices'!$C$14+O3 -> 13.16 | Z3: ='Blocking Prices'!$D$14+P3 -> 11.96 | AA3: ='Blocking Prices'!$E$14+Q3 -> 7.13 | AB3: ='Blocking Prices'!$F$14+R3 -> 5.27 | AC3: ='Blocking Prices'!$G$14+S3 -> 4.66 | AD3: ='Blocking Prices'!$H$14+T3 -> 4.33 | AE3: ='Blocking Prices'!$I$14+U3 -> 4.15 | AF3: ='Blocking Prices'!$J$14+V3 -> 3.94 | AG3: ='Blocking Prices'!$K$14+W3 -> 3.77 | AL3: <span data-sheets-root="1">Stay on top of your week with the Dorchester Horizon Pocket Diary - Week to View. Featuring a soft Vegan Leather Horizon design, white paper, and a ribbon marker, this compact diary combines style and practicality for easy weekly planning.</span>_x000D_\n<div class="trade-info">_x000D_\n<div class="trade-info__item">_x000D_\n<div class="product-popup-modal__text rte">_x000D_\n_x000D_\n&nbsp;_x000D_\n_x000D_\n</div>_x000D_\n</div>_x000D_\n</div> | AN3: =IFERROR(_xlfn.LET(_xlpm.v,INDEX('product-export-27-8-2026'!$A:$AJ,MATCH($A3,'product-export-27-8-2026'!$A:$A,0),MATCH(AN$1,'product-export-27-8-2026'!$1:$1,0)),IF(_xlpm.v="","",_xlpm.v)),"") | AO3: =IFERROR(_xlfn.LET(_xlpm.v,INDEX('product-export-27-8-2026'!$A:$AJ,MATCH($A3,'product-export-27-8-2026'!$A:$A,0),MATCH(AO$1,'product-export-27-8-2026'!$1:$1,0)),IF(_xlpm.v="","",_xlpm.v)),"") | AP3: =IFERROR(_xlfn.LET(_xlpm.v,INDEX('product-export-27-8-2026'!$A:$AJ,MATCH($A3,'product-export-27-8-2026'!$A:$A,0),MATCH(AP$1,'product-export-27-8-2026'!$1:$1,0)),IF(_xlpm.v="","",_xlpm.v)),"") | AQ3: =IFERROR(_xlfn.LET(_xlpm.v,INDEX('product-export-27-8-2026'!$A:$AJ,MATCH($A3,'product-export-27-8-2026'!$A:$A,0),MATCH(AQ$1,'product-export-27-8-2026'!$1:$1,0)),IF(_xlpm.v="","",_xlpm.v)),"") | AR3: =IFERROR(_xlfn.LET(_xlpm.v,INDEX('product-export-27-8-2026'!$A:$AJ,MATCH($A3,'product-export-27-8-2026'!$A:$A,0),MATCH(AR$1,'product-export-27-8-2026'!$1:$1,0)),IF(_xlpm.v="","",_xlpm.v)),"") -> Diaries, Dorchester Collection, Diaries > Pocket Diaries | AS3: =IFERROR(_xlfn.LET(_xlpm.v,INDEX('product-export-27-8-2026'!$A:$AJ,MATCH($A3,'product-export-27-8-2026'!$A:$A,0),MATCH(AS$1,'product-export-27-8-2026'!$1:$1,0)),IF(_xlpm.v="","",_xlpm.v)),"") -> Dorchester-Horizon-Pocket-Week-to-View
A4: 604 | B4: Dorchester Horizon Pocket, Week to View, Black-Grey | C4: Diary | D4: HZ-BK/GY-U-095 | E4: HZ-BK/GY-U-095 | F4: HZ96U | G4: Pocket | H4: Black-Grey | I4: Week to View | J4: White | K4: 18mm x 18mm | L4: 0.42 | M4: 9.99 | N4: 1:9.74;10:9.33;25:5.30;50:3.77;100:3.28;250:3.07;500:2.95;750:2.77;1000:2.63; | O4: =IFERROR(VALUE(_xlfn.TEXTBEFORE(_xlfn.TEXTAFTER(";"&$N4,";"&SUBSTITUTE(O$1,"Qty ","")&":"),";")),"") -> 9.74 | P4: =IFERROR(VALUE(_xlfn.TEXTBEFORE(_xlfn.TEXTAFTER(";"&$N4,";"&SUBSTITUTE(P$1,"Qty ","")&":"),";")),"") -> 9.33 | Q4: =IFERROR(VALUE(_xlfn.TEXTBEFORE(_xlfn.TEXTAFTER(";"&$N4,";"&SUBSTITUTE(Q$1,"Qty ","")&":"),";")),"") -> 5.3 | R4: =IFERROR(VALUE(_xlfn.TEXTBEFORE(_xlfn.TEXTAFTER(";"&$N4,";"&SUBSTITUTE(R$1,"Qty ","")&":"),";")),"") -> 3.77 | S4: =IFERROR(VALUE(_xlfn.TEXTBEFORE(_xlfn.TEXTAFTER(";"&$N4,";"&SUBSTITUTE(S$1,"Qty ","")&":"),";")),"") -> 3.28 | T4: =IFERROR(VALUE(_xlfn.TEXTBEFORE(_xlfn.TEXTAFTER(";"&$N4,";"&SUBSTITUTE(T$1,"Qty ","")&":"),";")),"") -> 3.07 | U4: =IFERROR(VALUE(_xlfn.TEXTBEFORE(_xlfn.TEXTAFTER(";"&$N4,";"&SUBSTITUTE(U$1,"Qty ","")&":"),";")),"") -> 2.95 | V4: =IFERROR(VALUE(_xlfn.TEXTBEFORE(_xlfn.TEXTAFTER(";"&$N4,";"&SUBSTITUTE(V$1,"Qty ","")&":"),";")),"") -> 2.77 | W4: =IFERROR(VALUE(_xlfn.TEXTBEFORE(_xlfn.TEXTAFTER(";"&$N4,";"&SUBSTITUTE(W$1,"Qty ","")&":"),";")),"") -> 2.63 | X4: {=IF(Y4="","",_xlfn.TEXTJOIN(";",TRUE,SUBSTITUTE($Y$1:$AG$1,"Qty ","")&":"&TEXT(Y4:AG4,"0.00"))&";")} -> 1:13.16;10:11.96;25:7.13;50:5.27;100:4.66;250:4.33;500:4.15;750:3.94;1000:3.77; | Y4: ='Blocking Prices'!$C$14+O4 -> 13.16 | Z4: ='Blocking Prices'!$D$14+P4 -> 11.96 | AA4: ='Blocking Prices'!$E$14+Q4 -> 7.13 | AB4: ='Blocking Prices'!$F$14+R4 -> 5.27 | AC4: ='Blocking Prices'!$G$14+S4 -> 4.66 | AD4: ='Blocking Prices'!$H$14+T4 -> 4.33 | AE4: ='Blocking Prices'!$I$14+U4 -> 4.15 | AF4: ='Blocking Prices'!$J$14+V4 -> 3.94 | AG4: ='Blocking Prices'!$K$14+W4 -> 3.77 | AL4: <span data-sheets-root="1">Stay on top of your week with the Dorchester Horizon Pocket Diary - Week to View. Featuring a soft Vegan Leather Horizon design, white paper, and a ribbon marker, this compact diary combines style and practicality for easy weekly planning.</span>_x000D_\n<div class="trade-info">_x000D_\n<div class="trade-info__item">_x000D_\n<div class="product-popup-modal__text rte">_x000D_\n_x000D_\n&nbsp;_x000D_\n_x000D_\n</div>_x000D_\n</div>_x000D_\n</div> | AN4: =IFERROR(_xlfn.LET(_xlpm.v,INDEX('product-export-27-8-2026'!$A:$AJ,MATCH($A4,'product-export-27-8-2026'!$A:$A,0),MATCH(AN$1,'product-export-27-8-2026'!$1:$1,0)),IF(_xlpm.v="","",_xlpm.v)),"") | AO4: =IFERROR(_xlfn.LET(_xlpm.v,INDEX('product-export-27-8-2026'!$A:$AJ,MATCH($A4,'product-export-27-8-2026'!$A:$A,0),MATCH(AO$1,'product-export-27-8-2026'!$1:$1,0)),IF(_xlpm.v="","",_xlpm.v)),"") | AP4: =IFERROR(_xlfn.LET(_xlpm.v,INDEX('product-export-27-8-2026'!$A:$AJ,MATCH($A4,'product-export-27-8-2026'!$A:$A,0),MATCH(AP$1,'product-export-27-8-2026'!$1:$1,0)),IF(_xlpm.v="","",_xlpm.v)),"") | AQ4: =IFERROR(_xlfn.LET(_xlpm.v,INDEX('product-export-27-8-2026'!$A:$AJ,MATCH($A4,'product-export-27-8-2026'!$A:$A,0),MATCH(AQ$1,'product-export-27-8-2026'!$1:$1,0)),IF(_xlpm.v="","",_xlpm.v)),"") | AR4: =IFERROR(_xlfn.LET(_xlpm.v,INDEX('product-export-27-8-2026'!$A:$AJ,MATCH($A4,'product-export-27-8-2026'!$A:$A,0),MATCH(AR$1,'product-export-27-8-2026'!$1:$1,0)),IF(_xlpm.v="","",_xlpm.v)),"") -> Diaries, Dorchester Collection, Diaries > Pocket Diaries | AS4: =IFERROR(_xlfn.LET(_xlpm.v,INDEX('product-export-27-8-2026'!$A:$AJ,MATCH($A4,'product-export-27-8-2026'!$A:$A,0),MATCH(AS$1,'product-export-27-8-2026'!$1:$1,0)),IF(_xlpm.v="","",_xlpm.v)),"") -> Dorchester-Horizon-Pocket-Week-to-View
A5: 607 | B5: Dorchester Horizon Pocket, Week to View, Black-Red | C5: Diary | D5: HZ-BK/RD-U-095 | E5: HZ-BK/RD-U-095 | F5: HZ96U | G5: Pocket | H5: Black-Red | I5: Week to View | J5: White | K5: 18mm x 18mm | L5: 0.42 | M5: 9.99 | N5: 1:9.74;10:9.33;25:5.30;50:3.77;100:3.28;250:3.07;500:2.95;750:2.77;1000:2.63; | O5: =IFERROR(VALUE(_xlfn.TEXTBEFORE(_xlfn.TEXTAFTER(";"&$N5,";"&SUBSTITUTE(O$1,"Qty ","")&":"),";")),"") -> 9.74 | P5: =IFERROR(VALUE(_xlfn.TEXTBEFORE(_xlfn.TEXTAFTER(";"&$N5,";"&SUBSTITUTE(P$1,"Qty ","")&":"),";")),"") -> 9.33 | Q5: =IFERROR(VALUE(_xlfn.TEXTBEFORE(_xlfn.TEXTAFTER(";"&$N5,";"&SUBSTITUTE(Q$1,"Qty ","")&":"),";")),"") -> 5.3 | R5: =IFERROR(VALUE(_xlfn.TEXTBEFORE(_xlfn.TEXTAFTER(";"&$N5,";"&SUBSTITUTE(R$1,"Qty ","")&":"),";")),"") -> 3.77 | S5: =IFERROR(VALUE(_xlfn.TEXTBEFORE(_xlfn.TEXTAFTER(";"&$N5,";"&SUBSTITUTE(S$1,"Qty ","")&":"),";")),"") -> 3.28 | T5: =IFERROR(VALUE(_xlfn.TEXTBEFORE(_xlfn.TEXTAFTER(";"&$N5,";"&SUBSTITUTE(T$1,"Qty ","")&":"),";")),"") -> 3.07 | U5: =IFERROR(VALUE(_xlfn.TEXTBEFORE(_xlfn.TEXTAFTER(";"&$N5,";"&SUBSTITUTE(U$1,"Qty ","")&":"),";")),"") -> 2.95 | V5: =IFERROR(VALUE(_xlfn.TEXTBEFORE(_xlfn.TEXTAFTER(";"&$N5,";"&SUBSTITUTE(V$1,"Qty ","")&":"),";")),"") -> 2.77 | W5: =IFERROR(VALUE(_xlfn.TEXTBEFORE(_xlfn.TEXTAFTER(";"&$N5,";"&SUBSTITUTE(W$1,"Qty ","")&":"),";")),"") -> 2.63 | X5: {=IF(Y5="","",_xlfn.TEXTJOIN(";",TRUE,SUBSTITUTE($Y$1:$AG$1,"Qty ","")&":"&TEXT(Y5:AG5,"0.00"))&";")} -> 1:13.16;10:11.96;25:7.13;50:5.27;100:4.66;250:4.33;500:4.15;750:3.94;1000:3.77; | Y5: ='Blocking Prices'!$C$14+O5 -> 13.16 | Z5: ='Blocking Prices'!$D$14+P5 -> 11.96 | AA5: ='Blocking Prices'!$E$14+Q5 -> 7.13 | AB5: ='Blocking Prices'!$F$14+R5 -> 5.27 | AC5: ='Blocking Prices'!$G$14+S5 -> 4.66 | AD5: ='Blocking Prices'!$H$14+T5 -> 4.33 | AE5: ='Blocking Prices'!$I$14+U5 -> 4.15 | AF5: ='Blocking Prices'!$J$14+V5 -> 3.94 | AG5: ='Blocking Prices'!$K$14+W5 -> 3.77 | AL5: <span data-sheets-root="1">Stay on top of your week with the Dorchester Horizon Pocket Diary - Week to View. Featuring a soft Vegan Leather Horizon design, white paper, and a ribbon marker, this compact diary combines style and practicality for easy weekly planning.</span>_x000D_\n<div class="trade-info">_x000D_\n<div class="trade-info__item">_x000D_\n<div class="product-popup-modal__text rte">_x000D_\n_x000D_\n&nbsp;_x000D_\n_x000D_\n</div>_x000D_\n</div>_x000D_\n</div> | AN5: =IFERROR(_xlfn.LET(_xlpm.v,INDEX('product-export-27-8-2026'!$A:$AJ,MATCH($A5,'product-export-27-8-2026'!$A:$A,0),MATCH(AN$1,'product-export-27-8-2026'!$1:$1,0)),IF(_xlpm.v="","",_xlpm.v)),"") | AO5: =IFERROR(_xlfn.LET(_xlpm.v,INDEX('product-export-27-8-2026'!$A:$AJ,MATCH($A5,'product-export-27-8-2026'!$A:$A,0),MATCH(AO$1,'product-export-27-8-2026'!$1:$1,0)),IF(_xlpm.v="","",_xlpm.v)),"") | AP5: =IFERROR(_xlfn.LET(_xlpm.v,INDEX('product-export-27-8-2026'!$A:$AJ,MATCH($A5,'product-export-27-8-2026'!$A:$A,0),MATCH(AP$1,'product-export-27-8-2026'!$1:$1,0)),IF(_xlpm.v="","",_xlpm.v)),"") | AQ5: =IFERROR(_xlfn.LET(_xlpm.v,INDEX('product-export-27-8-2026'!$A:$AJ,MATCH($A5,'product-export-27-8-2026'!$A:$A,0),MATCH(AQ$1,'product-export-27-8-2026'!$1:$1,0)),IF(_xlpm.v="","",_xlpm.v)),"") | AR5: =IFERROR(_xlfn.LET(_xlpm.v,INDEX('product-export-27-8-2026'!$A:$AJ,MATCH($A5,'product-export-27-8-2026'!$A:$A,0),MATCH(AR$1,'product-export-27-8-2026'!$1:$1,0)),IF(_xlpm.v="","",_xlpm.v)),"") -> Diaries, Dorchester Collection, Diaries > Pocket Diaries | AS5: =IFERROR(_xlfn.LET(_xlpm.v,INDEX('product-export-27-8-2026'!$A:$AJ,MATCH($A5,'product-export-27-8-2026'!$A:$A,0),MATCH(AS$1,'product-export-27-8-2026'!$1:$1,0)),IF(_xlpm.v="","",_xlpm.v)),"") -> Dorchester-Horizon-Pocket-Week-to-View
A6: 609 | B6: Dorchester Horizon Pocket, Week to View, Black-Yellow | C6: Diary | D6: HZ-BK/YE-U-095 | E6: HZ-BK/YE-U-095 | F6: HZ96U | G6: Pocket | H6: Black-Yellow | I6: Week to View | J6: White | K6: 18mm x 18mm | L6: 0.42 | M6: 9.99 | N6: 1:9.74;10:9.33;25:5.30;50:3.77;100:3.28;250:3.07;500:2.95;750:2.77;1000:2.63; | O6: =IFERROR(VALUE(_xlfn.TEXTBEFORE(_xlfn.TEXTAFTER(";"&$N6,";"&SUBSTITUTE(O$1,"Qty ","")&":"),";")),"") -> 9.74 | P6: =IFERROR(VALUE(_xlfn.TEXTBEFORE(_xlfn.TEXTAFTER(";"&$N6,";"&SUBSTITUTE(P$1,"Qty ","")&":"),";")),"") -> 9.33 | Q6: =IFERROR(VALUE(_xlfn.TEXTBEFORE(_xlfn.TEXTAFTER(";"&$N6,";"&SUBSTITUTE(Q$1,"Qty ","")&":"),";")),"") -> 5.3 | R6: =IFERROR(VALUE(_xlfn.TEXTBEFORE(_xlfn.TEXTAFTER(";"&$N6,";"&SUBSTITUTE(R$1,"Qty ","")&":"),";")),"") -> 3.77 | S6: =IFERROR(VALUE(_xlfn.TEXTBEFORE(_xlfn.TEXTAFTER(";"&$N6,";"&SUBSTITUTE(S$1,"Qty ","")&":"),";")),"") -> 3.28 | T6: =IFERROR(VALUE(_xlfn.TEXTBEFORE(_xlfn.TEXTAFTER(";"&$N6,";"&SUBSTITUTE(T$1,"Qty ","")&":"),";")),"") -> 3.07 | U6: =IFERROR(VALUE(_xlfn.TEXTBEFORE(_xlfn.TEXTAFTER(";"&$N6,";"&SUBSTITUTE(U$1,"Qty ","")&":"),";")),"") -> 2.95 | V6: =IFERROR(VALUE(_xlfn.TEXTBEFORE(_xlfn.TEXTAFTER(";"&$N6,";"&SUBSTITUTE(V$1,"Qty ","")&":"),";")),"") -> 2.77 | W6: =IFERROR(VALUE(_xlfn.TEXTBEFORE(_xlfn.TEXTAFTER(";"&$N6,";"&SUBSTITUTE(W$1,"Qty ","")&":"),";")),"") -> 2.63 | X6: {=IF(Y6="","",_xlfn.TEXTJOIN(";",TRUE,SUBSTITUTE($Y$1:$AG$1,"Qty ","")&":"&TEXT(Y6:AG6,"0.00"))&";")} -> 1:13.16;10:11.96;25:7.13;50:5.27;100:4.66;250:4.33;500:4.15;750:3.94;1000:3.77; | Y6: ='Blocking Prices'!$C$14+O6 -> 13.16 | Z6: ='Blocking Prices'!$D$14+P6 -> 11.96 | AA6: ='Blocking Prices'!$E$14+Q6 -> 7.13 | AB6: ='Blocking Prices'!$F$14+R6 -> 5.27 | AC6: ='Blocking Prices'!$G$14+S6 -> 4.66 | AD6: ='Blocking Prices'!$H$14+T6 -> 4.33 | AE6: ='Blocking Prices'!$I$14+U6 -> 4.15 | AF6: ='Blocking Prices'!$J$14+V6 -> 3.94 | AG6: ='Blocking Prices'!$K$14+W6 -> 3.77 | AL6: <span data-sheets-root="1">Stay on top of your week with the Dorchester Horizon Pocket Diary - Week to View. Featuring a soft Vegan Leather Horizon design, white paper, and a ribbon marker, this compact diary combines style and practicality for easy weekly planning.</span>_x000D_\n<div class="trade-info">_x000D_\n<div class="trade-info__item">_x000D_\n<div class="product-popup-modal__text rte">_x000D_\n_x000D_\n&nbsp;_x000D_\n_x000D_\n</div>_x000D_\n</div>_x000D_\n</div> | AN6: =IFERROR(_xlfn.LET(_xlpm.v,INDEX('product-export-27-8-2026'!$A:$AJ,MATCH($A6,'product-export-27-8-2026'!$A:$A,0),MATCH(AN$1,'product-export-27-8-2026'!$1:$1,0)),IF(_xlpm.v="","",_xlpm.v)),"") | AO6: =IFERROR(_xlfn.LET(_xlpm.v,INDEX('product-export-27-8-2026'!$A:$AJ,MATCH($A6,'product-export-27-8-2026'!$A:$A,0),MATCH(AO$1,'product-export-27-8-2026'!$1:$1,0)),IF(_xlpm.v="","",_xlpm.v)),"") | AP6: =IFERROR(_xlfn.LET(_xlpm.v,INDEX('product-export-27-8-2026'!$A:$AJ,MATCH($A6,'product-export-27-8-2026'!$A:$A,0),MATCH(AP$1,'product-export-27-8-2026'!$1:$1,0)),IF(_xlpm.v="","",_xlpm.v)),"") | AQ6: =IFERROR(_xlfn.LET(_xlpm.v,INDEX('product-export-27-8-2026'!$A:$AJ,MATCH($A6,'product-export-27-8-2026'!$A:$A,0),MATCH(AQ$1,'product-export-27-8-2026'!$1:$1,0)),IF(_xlpm.v="","",_xlpm.v)),"") | AR6: =IFERROR(_xlfn.LET(_xlpm.v,INDEX('product-export-27-8-2026'!$A:$AJ,MATCH($A6,'product-export-27-8-2026'!$A:$A,0),MATCH(AR$1,'product-export-27-8-2026'!$1:$1,0)),IF(_xlpm.v="","",_xlpm.v)),"") -> Diaries, Dorchester Collection, Diaries > Pocket Diaries | AS6: =IFERROR(_xlfn.LET(_xlpm.v,INDEX('product-export-27-8-2026'!$A:$AJ,MATCH($A6,'product-export-27-8-2026'!$A:$A,0),MATCH(AS$1,'product-export-27-8-2026'!$1:$1,0)),IF(_xlpm.v="","",_xlpm.v)),"") -> Dorchester-Horizon-Pocket-Week-to-View
A7: 611 | B7: Dorchester Horizon Pocket, Week to View, Green- Green | C7: Diary | D7: HZ-GN/GN-U-095 | E7: HZ-GN/GN-U-095 | F7: HZ96U | G7: Pocket | H7: Green-Green | I7: Week to View | J7: White | K7: 18mm x 18mm | L7: 0.42 | M7: 9.99 | N7: 1:9.74;10:9.33;25:5.30;50:3.77;100:3.28;250:3.07;500:2.95;750:2.77;1000:2.63; | O7: =IFERROR(VALUE(_xlfn.TEXTBEFORE(_xlfn.TEXTAFTER(";"&$N7,";"&SUBSTITUTE(O$1,"Qty ","")&":"),";")),"") -> 9.74 | P7: =IFERROR(VALUE(_xlfn.TEXTBEFORE(_xlfn.TEXTAFTER(";"&$N7,";"&SUBSTITUTE(P$1,"Qty ","")&":"),";")),"") -> 9.33 | Q7: =IFERROR(VALUE(_xlfn.TEXTBEFORE(_xlfn.TEXTAFTER(";"&$N7,";"&SUBSTITUTE(Q$1,"Qty ","")&":"),";")),"") -> 5.3 | R7: =IFERROR(VALUE(_xlfn.TEXTBEFORE(_xlfn.TEXTAFTER(";"&$N7,";"&SUBSTITUTE(R$1,"Qty ","")&":"),";")),"") -> 3.77 | S7: =IFERROR(VALUE(_xlfn.TEXTBEFORE(_xlfn.TEXTAFTER(";"&$N7,";"&SUBSTITUTE(S$1,"Qty ","")&":"),";")),"") -> 3.28 | T7: =IFERROR(VALUE(_xlfn.TEXTBEFORE(_xlfn.TEXTAFTER(";"&$N7,";"&SUBSTITUTE(T$1,"Qty ","")&":"),";")),"") -> 3.07 | U7: =IFERROR(VALUE(_xlfn.TEXTBEFORE(_xlfn.TEXTAFTER(";"&$N7,";"&SUBSTITUTE(U$1,"Qty ","")&":"),";")),"") -> 2.95 | V7: =IFERROR(VALUE(_xlfn.TEXTBEFORE(_xlfn.TEXTAFTER(";"&$N7,";"&SUBSTITUTE(V$1,"Qty ","")&":"),";")),"") -> 2.77 | W7: =IFERROR(VALUE(_xlfn.TEXTBEFORE(_xlfn.TEXTAFTER(";"&$N7,";"&SUBSTITUTE(W$1,"Qty ","")&":"),";")),"") -> 2.63 | X7: {=IF(Y7="","",_xlfn.TEXTJOIN(";",TRUE,SUBSTITUTE($Y$1:$AG$1,"Qty ","")&":"&TEXT(Y7:AG7,"0.00"))&";")} -> 1:13.16;10:11.96;25:7.13;50:5.27;100:4.66;250:4.33;500:4.15;750:3.94;1000:3.77; | Y7: ='Blocking Prices'!$C$14+O7 -> 13.16 | Z7: ='Blocking Prices'!$D$14+P7 -> 11.96 | AA7: ='Blocking Prices'!$E$14+Q7 -> 7.13 | AB7: ='Blocking Prices'!$F$14+R7 -> 5.27 | AC7: ='Blocking Prices'!$G$14+S7 -> 4.66 | AD7: ='Blocking Prices'!$H$14+T7 -> 4.33 | AE7: ='Blocking Prices'!$I$14+U7 -> 4.15 | AF7: ='Blocking Prices'!$J$14+V7 -> 3.94 | AG7: ='Blocking Prices'!$K$14+W7 -> 3.77 | AL7: <span data-sheets-root="1">Stay on top of your week with the Dorchester Horizon Pocket Diary - Week to View. Featuring a soft Vegan Leather Horizon design, white paper, and a ribbon marker, this compact diary combines style and practicality for easy weekly planning.</span>_x000D_\n<div class="trade-info">_x000D_\n<div class="trade-info__item">_x000D_\n<div class="product-popup-modal__text rte">_x000D_\n_x000D_\n&nbsp;_x000D_\n_x000D_\n</div>_x000D_\n</div>_x000D_\n</div> | AN7: =IFERROR(_xlfn.LET(_xlpm.v,INDEX('product-export-27-8-2026'!$A:$AJ,MATCH($A7,'product-export-27-8-2026'!$A:$A,0),MATCH(AN$1,'product-export-27-8-2026'!$1:$1,0)),IF(_xlpm.v="","",_xlpm.v)),"") | AO7: =IFERROR(_xlfn.LET(_xlpm.v,INDEX('product-export-27-8-2026'!$A:$AJ,MATCH($A7,'product-export-27-8-2026'!$A:$A,0),MATCH(AO$1,'product-export-27-8-2026'!$1:$1,0)),IF(_xlpm.v="","",_xlpm.v)),"") | AP7: =IFERROR(_xlfn.LET(_xlpm.v,INDEX('product-export-27-8-2026'!$A:$AJ,MATCH($A7,'product-export-27-8-2026'!$A:$A,0),MATCH(AP$1,'product-export-27-8-2026'!$1:$1,0)),IF(_xlpm.v="","",_xlpm.v)),"") | AQ7: =IFERROR(_xlfn.LET(_xlpm.v,INDEX('product-export-27-8-2026'!$A:$AJ,MATCH($A7,'product-export-27-8-2026'!$A:$A,0),MATCH(AQ$1,'product-export-27-8-2026'!$1:$1,0)),IF(_xlpm.v="","",_xlpm.v)),"") | AR7: =IFERROR(_xlfn.LET(_xlpm.v,INDEX('product-export-27-8-2026'!$A:$AJ,MATCH($A7,'product-export-27-8-2026'!$A:$A,0),MATCH(AR$1,'product-export-27-8-2026'!$1:$1,0)),IF(_xlpm.v="","",_xlpm.v)),"") -> Diaries, Dorchester Collection, Diaries > Pocket Diaries | AS7: =IFERROR(_xlfn.LET(_xlpm.v,INDEX('product-export-27-8-2026'!$A:$AJ,MATCH($A7,'product-export-27-8-2026'!$A:$A,0),MATCH(AS$1,'product-export-27-8-2026'!$1:$1,0)),IF(_xlpm.v="","",_xlpm.v)),"") -> Dorchester-Horizon-Pocket-Week-to-View
A8: 613 | B8: Dorchester Horizon Pocket, Week to View, Royal Blue | C8: Diary | D8: HZ-BK/RB-U-095 | E8: HZ-BK/RB-U-095 | F8: HZ96U | G8: Pocket | H8: Royal Blue | I8: Week to View | J8: White | K8: 18mm x 18mm | L8: 0.42 | M8: 9.99 | N8: 1:9.74;10:9.33;25:5.30;50:3.77;100:3.28;250:3.07;500:2.95;750:2.77;1000:2.63; | O8: =IFERROR(VALUE(_xlfn.TEXTBEFORE(_xlfn.TEXTAFTER(";"&$N8,";"&SUBSTITUTE(O$1,"Qty ","")&":"),";")),"") -> 9.74 | P8: =IFERROR(VALUE(_xlfn.TEXTBEFORE(_xlfn.TEXTAFTER(";"&$N8,";"&SUBSTITUTE(P$1,"Qty ","")&":"),";")),"") -> 9.33 | Q8: =IFERROR(VALUE(_xlfn.TEXTBEFORE(_xlfn.TEXTAFTER(";"&$N8,";"&SUBSTITUTE(Q$1,"Qty ","")&":"),";")),"") -> 5.3 | R8: =IFERROR(VALUE(_xlfn.TEXTBEFORE(_xlfn.TEXTAFTER(";"&$N8,";"&SUBSTITUTE(R$1,"Qty ","")&":"),";")),"") -> 3.77 | S8: =IFERROR(VALUE(_xlfn.TEXTBEFORE(_xlfn.TEXTAFTER(";"&$N8,";"&SUBSTITUTE(S$1,"Qty ","")&":"),";")),"") -> 3.28 | T8: =IFERROR(VALUE(_xlfn.TEXTBEFORE(_xlfn.TEXTAFTER(";"&$N8,";"&SUBSTITUTE(T$1,"Qty ","")&":"),";")),"") -> 3.07 | U8: =IFERROR(VALUE(_xlfn.TEXTBEFORE(_xlfn.TEXTAFTER(";"&$N8,";"&SUBSTITUTE(U$1,"Qty ","")&":"),";")),"") -> 2.95 | V8: =IFERROR(VALUE(_xlfn.TEXTBEFORE(_xlfn.TEXTAFTER(";"&$N8,";"&SUBSTITUTE(V$1,"Qty ","")&":"),";")),"") -> 2.77 | W8: =IFERROR(VALUE(_xlfn.TEXTBEFORE(_xlfn.TEXTAFTER(";"&$N8,";"&SUBSTITUTE(W$1,"Qty ","")&":"),";")),"") -> 2.63 | X8: {=IF(Y8="","",_xlfn.TEXTJOIN(";",TRUE,SUBSTITUTE($Y$1:$AG$1,"Qty ","")&":"&TEXT(Y8:AG8,"0.00"))&";")} -> 1:13.16;10:11.96;25:7.13;50:5.27;100:4.66;250:4.33;500:4.15;750:3.94;1000:3.77; | Y8: ='Blocking Prices'!$C$14+O8 -> 13.16 | Z8: ='Blocking Prices'!$D$14+P8 -> 11.96 | AA8: ='Blocking Prices'!$E$14+Q8 -> 7.13 | AB8: ='Blocking Prices'!$F$14+R8 -> 5.27 | AC8: ='Blocking Prices'!$G$14+S8 -> 4.66 | AD8: ='Blocking Prices'!$H$14+T8 -> 4.33 | AE8: ='Blocking Prices'!$I$14+U8 -> 4.15 | AF8: ='Blocking Prices'!$J$14+V8 -> 3.94 | AG8: ='Blocking Prices'!$K$14+W8 -> 3.77 | AL8: <span data-sheets-root="1">Stay on top of your week with the Dorchester Horizon Pocket Diary - Week to View. Featuring a soft Vegan Leather Horizon design, white paper, and a ribbon marker, this compact diary combines style and practicality for easy weekly planning.</span>_x000D_\n<div class="trade-info">_x000D_\n<div class="trade-info__item">_x000D_\n<div class="product-popup-modal__text rte">_x000D_\n_x000D_\n&nbsp;_x000D_\n_x000D_\n</div>_x000D_\n</div>_x000D_\n</div> | AN8: =IFERROR(_xlfn.LET(_xlpm.v,INDEX('product-export-27-8-2026'!$A:$AJ,MATCH($A8,'product-export-27-8-2026'!$A:$A,0),MATCH(AN$1,'product-export-27-8-2026'!$1:$1,0)),IF(_xlpm.v="","",_xlpm.v)),"") | AO8: =IFERROR(_xlfn.LET(_xlpm.v,INDEX('product-export-27-8-2026'!$A:$AJ,MATCH($A8,'product-export-27-8-2026'!$A:$A,0),MATCH(AO$1,'product-export-27-8-2026'!$1:$1,0)),IF(_xlpm.v="","",_xlpm.v)),"") | AP8: =IFERROR(_xlfn.LET(_xlpm.v,INDEX('product-export-27-8-2026'!$A:$AJ,MATCH($A8,'product-export-27-8-2026'!$A:$A,0),MATCH(AP$1,'product-export-27-8-2026'!$1:$1,0)),IF(_xlpm.v="","",_xlpm.v)),"") | AQ8: =IFERROR(_xlfn.LET(_xlpm.v,INDEX('product-export-27-8-2026'!$A:$AJ,MATCH($A8,'product-export-27-8-2026'!$A:$A,0),MATCH(AQ$1,'product-export-27-8-2026'!$1:$1,0)),IF(_xlpm.v="","",_xlpm.v)),"") | AR8: =IFERROR(_xlfn.LET(_xlpm.v,INDEX('product-export-27-8-2026'!$A:$AJ,MATCH($A8,'product-export-27-8-2026'!$A:$A,0),MATCH(AR$1,'product-export-27-8-2026'!$1:$1,0)),IF(_xlpm.v="","",_xlpm.v)),"") -> Diaries, Dorchester Collection, Diaries > Pocket Diaries | AS8: =IFERROR(_xlfn.LET(_xlpm.v,INDEX('product-export-27-8-2026'!$A:$AJ,MATCH($A8,'product-export-27-8-2026'!$A:$A,0),MATCH(AS$1,'product-export-27-8-2026'!$1:$1,0)),IF(_xlpm.v="","",_xlpm.v)),"") -> Dorchester-Horizon-Pocket-Week-to-View
A9: 615 | B9: Dorchester Bicolor Pocket, Week to View, Black-Aqua | C9: Diary | D9: NB-BK/AQ-U-096 | E9: NB-BK/AQ-U-096 | F9: NB96U | G9: Pocket | H9: Black-Aqua | I9: Week to View | J9: Cream | K9: 18mm x 18mm | L9: 0.42 | M9: 9.99 | N9: 1:9.74;10:9.33;25:5.30;50:3.77;100:3.28;250:3.07;500:2.95;750:2.77;1000:2.63; | O9: =IFERROR(VALUE(_xlfn.TEXTBEFORE(_xlfn.TEXTAFTER(";"&$N9,";"&SUBSTITUTE(O$1,"Qty ","")&":"),";")),"") -> 9.74 | P9: =IFERROR(VALUE(_xlfn.TEXTBEFORE(_xlfn.TEXTAFTER(";"&$N9,";"&SUBSTITUTE(P$1,"Qty ","")&":"),";")),"") -> 9.33 | Q9: =IFERROR(VALUE(_xlfn.TEXTBEFORE(_xlfn.TEXTAFTER(";"&$N9,";"&SUBSTITUTE(Q$1,"Qty ","")&":"),";")),"") -> 5.3 | R9: =IFERROR(VALUE(_xlfn.TEXTBEFORE(_xlfn.TEXTAFTER(";"&$N9,";"&SUBSTITUTE(R$1,"Qty ","")&":"),";")),"") -> 3.77 | S9: =IFERROR(VALUE(_xlfn.TEXTBEFORE(_xlfn.TEXTAFTER(";"&$N9,";"&SUBSTITUTE(S$1,"Qty ","")&":"),";")),"") -> 3.28 | T9: =IFERROR(VALUE(_xlfn.TEXTBEFORE(_xlfn.TEXTAFTER(";"&$N9,";"&SUBSTITUTE(T$1,"Qty ","")&":"),";")),"") -> 3.07 | U9: =IFERROR(VALUE(_xlfn.TEXTBEFORE(_xlfn.TEXTAFTER(";"&$N9,";"&SUBSTITUTE(U$1,"Qty ","")&":"),";")),"") -> 2.95 | V9: =IFERROR(VALUE(_xlfn.TEXTBEFORE(_xlfn.TEXTAFTER(";"&$N9,";"&SUBSTITUTE(V$1,"Qty ","")&":"),";")),"") -> 2.77 | W9: =IFERROR(VALUE(_xlfn.TEXTBEFORE(_xlfn.TEXTAFTER(";"&$N9,";"&SUBSTITUTE(W$1,"Qty ","")&":"),";")),"") -> 2.63 | X9: {=IF(Y9="","",_xlfn.TEXTJOIN(";",TRUE,SUBSTITUTE($Y$1:$AG$1,"Qty ","")&":"&TEXT(Y9:AG9,"0.00"))&";")} -> 1:13.16;10:11.96;25:7.13;50:5.27;100:4.66;250:4.33;500:4.15;750:3.94;1000:3.77; | Y9: ='Blocking Prices'!$C$14+O9 -> 13.16 | Z9: ='Blocking Prices'!$D$14+P9 -> 11.96 | AA9: ='Blocking Prices'!$E$14+Q9 -> 7.13 | AB9: ='Blocking Prices'!$F$14+R9 -> 5.27 | AC9: ='Blocking Prices'!$G$14+S9 -> 4.66 | AD9: ='Blocking Prices'!$H$14+T9 -> 4.33 | AE9: ='Blocking Prices'!$I$14+U9 -> 4.15 | AF9: ='Blocking Prices'!$J$14+V9 -> 3.94 | AG9: ='Blocking Prices'!$K$14+W9 -> 3.77 | AL9: Stay organized in style with the Dorchester Bicolor Pocket Diary - Week to View. Featuring a unique bicolour design, cream paper, and a ribbon marker, it offers sophisticated weekly planning in a portable, compact size._x000D_\n<div class="trade-info">_x000D_\n<div class="trade-info__item">_x000D_\n<div class="product-popup-modal__text rte">_x000D_\n_x000D_\n&nbsp;_x000D_\n_x000D_\n</div>_x000D_\n</div>_x000D_\n</div> | AN9: =IFERROR(_xlfn.LET(_xlpm.v,INDEX('product-export-27-8-2026'!$A:$AJ,MATCH($A9,'product-export-27-8-2026'!$A:$A,0),MATCH(AN$1,'product-export-27-8-2026'!$1:$1,0)),IF(_xlpm.v="","",_xlpm.v)),"") | AO9: =IFERROR(_xlfn.LET(_xlpm.v,INDEX('product-export-27-8-2026'!$A:$AJ,MATCH($A9,'product-export-27-8-2026'!$A:$A,0),MATCH(AO$1,'product-export-27-8-2026'!$1:$1,0)),IF(_xlpm.v="","",_xlpm.v)),"") | AP9: =IFERROR(_xlfn.LET(_xlpm.v,INDEX('product-export-27-8-2026'!$A:$AJ,MATCH($A9,'product-export-27-8-2026'!$A:$A,0),MATCH(AP$1,'product-export-27-8-2026'!$1:$1,0)),IF(_xlpm.v="","",_xlpm.v)),"") | AQ9: =IFERROR(_xlfn.LET(_xlpm.v,INDEX('product-export-27-8-2026'!$A:$AJ,MATCH($A9,'product-export-27-8-2026'!$A:$A,0),MATCH(AQ$1,'product-export-27-8-2026'!$1:$1,0)),IF(_xlpm.v="","",_xlpm.v)),"") | AR9: =IFERROR(_xlfn.LET(_xlpm.v,INDEX('product-export-27-8-2026'!$A:$AJ,MATCH($A9,'product-export-27-8-2026'!$A:$A,0),MATCH(AR$1,'product-export-27-8-2026'!$1:$1,0)),IF(_xlpm.v="","",_xlpm.v)),"") -> Diaries, Dorchester Collection, Diaries > Pocket Diaries | AS9: =IFERROR(_xlfn.LET(_xlpm.v,INDEX('product-export-27-8-2026'!$A:$AJ,MATCH($A9,'product-export-27-8-2026'!$A:$A,0),MATCH(AS$1,'product-export-27-8-2026'!$1:$1,0)),IF(_xlpm.v="","",_xlpm.v)),"") -> Dorchester-Newhide-Bicolor-Pocket-Week-to-View
A10: 618 | B10: Dorchester Bicolor Pocket, Week to View, Black-Orange | C10: Diary | D10: NB-BK/OR-U-096 | E10: NB-BK/OR-U-096 | F10: NB96U | G10: Pocket | H10: Black-Orange | I10: Week to View | J10: Cream | K10: 18mm x 18mm | L10: 0.42 | M10: 9.99 | N10: 1:9.74;10:9.33;25:5.30;50:3.77;100:3.28;250:3.07;500:2.95;750:2.77;1000:2.63; | O10: =IFERROR(VALUE(_xlfn.TEXTBEFORE(_xlfn.TEXTAFTER(";"&$N10,";"&SUBSTITUTE(O$1,"Qty ","")&":"),";")),"") -> 9.74 | P10: =IFERROR(VALUE(_xlfn.TEXTBEFORE(_xlfn.TEXTAFTER(";"&$N10,";"&SUBSTITUTE(P$1,"Qty ","")&":"),";")),"") -> 9.33 | Q10: =IFERROR(VALUE(_xlfn.TEXTBEFORE(_xlfn.TEXTAFTER(";"&$N10,";"&SUBSTITUTE(Q$1,"Qty ","")&":"),";")),"") -> 5.3 | R10: =IFERROR(VALUE(_xlfn.TEXTBEFORE(_xlfn.TEXTAFTER(";"&$N10,";"&SUBSTITUTE(R$1,"Qty ","")&":"),";")),"") -> 3.77 | S10: =IFERROR(VALUE(_xlfn.TEXTBEFORE(_xlfn.TEXTAFTER(";"&$N10,";"&SUBSTITUTE(S$1,"Qty ","")&":"),";")),"") -> 3.28 | T10: =IFERROR(VALUE(_xlfn.TEXTBEFORE(_xlfn.TEXTAFTER(";"&$N10,";"&SUBSTITUTE(T$1,"Qty ","")&":"),";")),"") -> 3.07 | U10: =IFERROR(VALUE(_xlfn.TEXTBEFORE(_xlfn.TEXTAFTER(";"&$N10,";"&SUBSTITUTE(U$1,"Qty ","")&":"),";")),"") -> 2.95 | V10: =IFERROR(VALUE(_xlfn.TEXTBEFORE(_xlfn.TEXTAFTER(";"&$N10,";"&SUBSTITUTE(V$1,"Qty ","")&":"),";")),"") -> 2.77 | W10: =IFERROR(VALUE(_xlfn.TEXTBEFORE(_xlfn.TEXTAFTER(";"&$N10,";"&SUBSTITUTE(W$1,"Qty ","")&":"),";")),"") -> 2.63 | X10: {=IF(Y10="","",_xlfn.TEXTJOIN(";",TRUE,SUBSTITUTE($Y$1:$AG$1,"Qty ","")&":"&TEXT(Y10:AG10,"0.00"))&";")} -> 1:13.16;10:11.96;25:7.13;50:5.27;100:4.66;250:4.33;500:4.15;750:3.94;1000:3.77; | Y10: ='Blocking Prices'!$C$14+O10 -> 13.16 | Z10: ='Blocking Prices'!$D$14+P10 -> 11.96 | AA10: ='Blocking Prices'!$E$14+Q10 -> 7.13 | AB10: ='Blocking Prices'!$F$14+R10 -> 5.27 | AC10: ='Blocking Prices'!$G$14+S10 -> 4.66 | AD10: ='Blocking Prices'!$H$14+T10 -> 4.33 | AE10: ='Blocking Prices'!$I$14+U10 -> 4.15 | AF10: ='Blocking Prices'!$J$14+V10 -> 3.94 | AG10: ='Blocking Prices'!$K$14+W10 -> 3.77 | AL10: Stay organized in style with the Dorchester Bicolor Pocket Diary - Week to View. Featuring a unique bicolour design, cream paper, and a ribbon marker, it offers sophisticated weekly planning in a portable, compact size._x000D_\n<div class="trade-info">_x000D_\n<div class="trade-info__item">_x000D_\n<div class="product-popup-modal__text rte">_x000D_\n_x000D_\n&nbsp;_x000D_\n_x000D_\n</div>_x000D_\n</div>_x000D_\n</div> | AN10: =IFERROR(_xlfn.LET(_xlpm.v,INDEX('product-export-27-8-2026'!$A:$AJ,MATCH($A10,'product-export-27-8-2026'!$A:$A,0),MATCH(AN$1,'product-export-27-8-2026'!$1:$1,0)),IF(_xlpm.v="","",_xlpm.v)),"") | AO10: =IFERROR(_xlfn.LET(_xlpm.v,INDEX('product-export-27-8-2026'!$A:$AJ,MATCH($A10,'product-export-27-8-2026'!$A:$A,0),MATCH(AO$1,'product-export-27-8-2026'!$1:$1,0)),IF(_xlpm.v="","",_xlpm.v)),"") | AP10: =IFERROR(_xlfn.LET(_xlpm.v,INDEX('product-export-27-8-2026'!$A:$AJ,MATCH($A10,'product-export-27-8-2026'!$A:$A,0),MATCH(AP$1,'product-export-27-8-2026'!$1:$1,0)),IF(_xlpm.v="","",_xlpm.v)),"") | AQ10: =IFERROR(_xlfn.LET(_xlpm.v,INDEX('product-export-27-8-2026'!$A:$AJ,MATCH($A10,'product-export-27-8-2026'!$A:$A,0),MATCH(AQ$1,'product-export-27-8-2026'!$1:$1,0)),IF(_xlpm.v="","",_xlpm.v)),"") | AR10: =IFERROR(_xlfn.LET(_xlpm.v,INDEX('product-export-27-8-2026'!$A:$AJ,MATCH($A10,'product-export-27-8-2026'!$A:$A,0),MATCH(AR$1,'product-export-27-8-2026'!$1:$1,0)),IF(_xlpm.v="","",_xlpm.v)),"") -> Diaries, Dorchester Collection, Diaries > Pocket Diaries | AS10: =IFERROR(_xlfn.LET(_xlpm.v,INDEX('product-export-27-8-2026'!$A:$AJ,MATCH($A10,'product-export-27-8-2026'!$A:$A,0),MATCH(AS$1,'product-export-27-8-2026'!$1:$1,0)),IF(_xlpm.v="","",_xlpm.v)),"") -> Dorchester-Newhide-Bicolor-Pocket-Week-to-View
A11: 620 | B11: Dorchester Bicolor Pocket, Week to View, Black-Purple | C11: Diary | D11: NB-BK/PU-U-096 | E11: NB-BK/PU-U-096 | F11: NB96U | G11: Pocket | H11: Black-Purple | I11: Week to View | J11: Cream | K11: 18mm x 18mm | L11: 0.42 | M11: 9.99 | N11: 1:9.74;10:9.33;25:5.30;50:3.77;100:3.28;250:3.07;500:2.95;750:2.77;1000:2.63; | O11: =IFERROR(VALUE(_xlfn.TEXTBEFORE(_xlfn.TEXTAFTER(";"&$N11,";"&SUBSTITUTE(O$1,"Qty ","")&":"),";")),"") -> 9.74 | P11: =IFERROR(VALUE(_xlfn.TEXTBEFORE(_xlfn.TEXTAFTER(";"&$N11,";"&SUBSTITUTE(P$1,"Qty ","")&":"),";")),"") -> 9.33 | Q11: =IFERROR(VALUE(_xlfn.TEXTBEFORE(_xlfn.TEXTAFTER(";"&$N11,";"&SUBSTITUTE(Q$1,"Qty ","")&":"),";")),"") -> 5.3 | R11: =IFERROR(VALUE(_xlfn.TEXTBEFORE(_xlfn.TEXTAFTER(";"&$N11,";"&SUBSTITUTE(R$1,"Qty ","")&":"),";")),"") -> 3.77 | S11: =IFERROR(VALUE(_xlfn.TEXTBEFORE(_xlfn.TEXTAFTER(";"&$N11,";"&SUBSTITUTE(S$1,"Qty ","")&":"),";")),"") -> 3.28 | T11: =IFERROR(VALUE(_xlfn.TEXTBEFORE(_xlfn.TEXTAFTER(";"&$N11,";"&SUBSTITUTE(T$1,"Qty ","")&":"),";")),"") -> 3.07 | U11: =IFERROR(VALUE(_xlfn.TEXTBEFORE(_xlfn.TEXTAFTER(";"&$N11,";"&SUBSTITUTE(U$1,"Qty ","")&":"),";")),"") -> 2.95 | V11: =IFERROR(VALUE(_xlfn.TEXTBEFORE(_xlfn.TEXTAFTER(";"&$N11,";"&SUBSTITUTE(V$1,"Qty ","")&":"),";")),"") -> 2.77 | W11: =IFERROR(VALUE(_xlfn.TEXTBEFORE(_xlfn.TEXTAFTER(";"&$N11,";"&SUBSTITUTE(W$1,"Qty ","")&":"),";")),"") -> 2.63 | X11: {=IF(Y11="","",_xlfn.TEXTJOIN(";",TRUE,SUBSTITUTE($Y$1:$AG$1,"Qty ","")&":"&TEXT(Y11:AG11,"0.00"))&";")} -> 1:13.16;10:11.96;25:7.13;50:5.27;100:4.66;250:4.33;500:4.15;750:3.94;1000:3.77; | Y11: ='Blocking Prices'!$C$14+O11 -> 13.16 | Z11: ='Blocking Prices'!$D$14+P11 -> 11.96 | AA11: ='Blocking Prices'!$E$14+Q11 -> 7.13 | AB11: ='Blocking Prices'!$F$14+R11 -> 5.27 | AC11: ='Blocking Prices'!$G$14+S11 -> 4.66 | AD11: ='Blocking Prices'!$H$14+T11 -> 4.33 | AE11: ='Blocking Prices'!$I$14+U11 -> 4.15 | AF11: ='Blocking Prices'!$J$14+V11 -> 3.94 | AG11: ='Blocking Prices'!$K$14+W11 -> 3.77 | AL11: Stay organized in style with the Dorchester Bicolor Pocket Diary - Week to View. Featuring a unique bicolour design, cream paper, and a ribbon marker, it offers sophisticated weekly planning in a portable, compact size._x000D_\n<div class="trade-info">_x000D_\n<div class="trade-info__item">_x000D_\n<div class="product-popup-modal__text rte">_x000D_\n_x000D_\n&nbsp;_x000D_\n_x000D_\n</div>_x000D_\n</div>_x000D_\n</div> | AN11: =IFERROR(_xlfn.LET(_xlpm.v,INDEX('product-export-27-8-2026'!$A:$AJ,MATCH($A11,'product-export-27-8-2026'!$A:$A,0),MATCH(AN$1,'product-export-27-8-2026'!$1:$1,0)),IF(_xlpm.v="","",_xlpm.v)),"") | AO11: =IFERROR(_xlfn.LET(_xlpm.v,INDEX('product-export-27-8-2026'!$A:$AJ,MATCH($A11,'product-export-27-8-2026'!$A:$A,0),MATCH(AO$1,'product-export-27-8-2026'!$1:$1,0)),IF(_xlpm.v="","",_xlpm.v)),"") | AP11: =IFERROR(_xlfn.LET(_xlpm.v,INDEX('product-export-27-8-2026'!$A:$AJ,MATCH($A11,'product-export-27-8-2026'!$A:$A,0),MATCH(AP$1,'product-export-27-8-2026'!$1:$1,0)),IF(_xlpm.v="","",_xlpm.v)),"") | AQ11: =IFERROR(_xlfn.LET(_xlpm.v,INDEX('product-export-27-8-2026'!$A:$AJ,MATCH($A11,'product-export-27-8-2026'!$A:$A,0),MATCH(AQ$1,'product-export-27-8-2026'!$1:$1,0)),IF(_xlpm.v="","",_xlpm.v)),"") | AR11: =IFERROR(_xlfn.LET(_xlpm.v,INDEX('product-export-27-8-2026'!$A:$AJ,MATCH($A11,'product-export-27-8-2026'!$A:$A,0),MATCH(AR$1,'product-export-27-8-2026'!$1:$1,0)),IF(_xlpm.v="","",_xlpm.v)),"") -> Diaries, Dorchester Collection, Diaries > Pocket Diaries | AS11: =IFERROR(_xlfn.LET(_xlpm.v,INDEX('product-export-27-8-2026'!$A:$AJ,MATCH($A11,'product-export-27-8-2026'!$A:$A,0),MATCH(AS$1,'product-export-27-8-2026'!$1:$1,0)),IF(_xlpm.v="","",_xlpm.v)),"") -> Dorchester-Newhide-Bicolor-Pocket-Week-to-View
A12: 622 | B12: Dorchester Bicolor Pocket, Week to View, Black-Red | C12: Diary | D12: NB-BK/RD-U-096 | E12: NB-BK/RD-U-096 | F12: NB96U | G12: Pocket | H12: Black-Red | I12: Week to View | J12: Cream | K12: 18mm x 18mm | L12: 0.42 | M12: 9.99 | N12: 1:9.74;10:9.33;25:5.30;50:3.77;100:3.28;250:3.07;500:2.95;750:2.77;1000:2.63; | O12: =IFERROR(VALUE(_xlfn.TEXTBEFORE(_xlfn.TEXTAFTER(";"&$N12,";"&SUBSTITUTE(O$1,"Qty ","")&":"),";")),"") -> 9.74 | P12: =IFERROR(VALUE(_xlfn.TEXTBEFORE(_xlfn.TEXTAFTER(";"&$N12,";"&SUBSTITUTE(P$1,"Qty ","")&":"),";")),"") -> 9.33 | Q12: =IFERROR(VALUE(_xlfn.TEXTBEFORE(_xlfn.TEXTAFTER(";"&$N12,";"&SUBSTITUTE(Q$1,"Qty ","")&":"),";")),"") -> 5.3 | R12: =IFERROR(VALUE(_xlfn.TEXTBEFORE(_xlfn.TEXTAFTER(";"&$N12,";"&SUBSTITUTE(R$1,"Qty ","")&":"),";")),"") -> 3.77 | S12: =IFERROR(VALUE(_xlfn.TEXTBEFORE(_xlfn.TEXTAFTER(";"&$N12,";"&SUBSTITUTE(S$1,"Qty ","")&":"),";")),"") -> 3.28 | T12: =IFERROR(VALUE(_xlfn.TEXTBEFORE(_xlfn.TEXTAFTER(";"&$N12,";"&SUBSTITUTE(T$1,"Qty ","")&":"),";")),"") -> 3.07 | U12: =IFERROR(VALUE(_xlfn.TEXTBEFORE(_xlfn.TEXTAFTER(";"&$N12,";"&SUBSTITUTE(U$1,"Qty ","")&":"),";")),"") -> 2.95 | V12: =IFERROR(VALUE(_xlfn.TEXTBEFORE(_xlfn.TEXTAFTER(";"&$N12,";"&SUBSTITUTE(V$1,"Qty ","")&":"),";")),"") -> 2.77 | W12: =IFERROR(VALUE(_xlfn.TEXTBEFORE(_xlfn.TEXTAFTER(";"&$N12,";"&SUBSTITUTE(W$1,"Qty ","")&":"),";")),"") -> 2.63 | X12: {=IF(Y12="","",_xlfn.TEXTJOIN(";",TRUE,SUBSTITUTE($Y$1:$AG$1,"Qty ","")&":"&TEXT(Y12:AG12,"0.00"))&";")} -> 1:13.16;10:11.96;25:7.13;50:5.27;100:4.66;250:4.33;500:4.15;750:3.94;1000:3.77; | Y12: ='Blocking Prices'!$C$14+O12 -> 13.16 | Z12: ='Blocking Prices'!$D$14+P12 -> 11.96 | AA12: ='Blocking Prices'!$E$14+Q12 -> 7.13 | AB12: ='Blocking Prices'!$F$14+R12 -> 5.27 | AC12: ='Blocking Prices'!$G$14+S12 -> 4.66 | AD12: ='Blocking Prices'!$H$14+T12 -> 4.33 | AE12: ='Blocking Prices'!$I$14+U12 -> 4.15 | AF12: ='Blocking Prices'!$J$14+V12 -> 3.94 | AG12: ='Blocking Prices'!$K$14+W12 -> 3.77 | AL12: Stay organized in style with the Dorchester Bicolor Pocket Diary - Week to View. Featuring a unique bicolour design, cream paper, and a ribbon marker, it offers sophisticated weekly planning in a portable, compact size. | AN12: =IFERROR(_xlfn.LET(_xlpm.v,INDEX('product-export-27-8-2026'!$A:$AJ,MATCH($A12,'product-export-27-8-2026'!$A:$A,0),MATCH(AN$1,'product-export-27-8-2026'!$1:$1,0)),IF(_xlpm.v="","",_xlpm.v)),"") | AO12: =IFERROR(_xlfn.LET(_xlpm.v,INDEX('product-export-27-8-2026'!$A:$AJ,MATCH($A12,'product-export-27-8-2026'!$A:$A,0),MATCH(AO$1,'product-export-27-8-2026'!$1:$1,0)),IF(_xlpm.v="","",_xlpm.v)),"") | AP12: =IFERROR(_xlfn.LET(_xlpm.v,INDEX('product-export-27-8-2026'!$A:$AJ,MATCH($A12,'product-export-27-8-2026'!$A:$A,0),MATCH(AP$1,'product-export-27-8-2026'!$1:$1,0)),IF(_xlpm.v="","",_xlpm.v)),"") | AQ12: =IFERROR(_xlfn.LET(_xlpm.v,INDEX('product-export-27-8-2026'!$A:$AJ,MATCH($A12,'product-export-27-8-2026'!$A:$A,0),MATCH(AQ$1,'product-export-27-8-2026'!$1:$1,0)),IF(_xlpm.v="","",_xlpm.v)),"") | AR12: =IFERROR(_xlfn.LET(_xlpm.v,INDEX('product-export-27-8-2026'!$A:$AJ,MATCH($A12,'product-export-27-8-2026'!$A:$A,0),MATCH(AR$1,'product-export-27-8-2026'!$1:$1,0)),IF(_xlpm.v="","",_xlpm.v)),"") -> Diaries, Dorchester Collection, Diaries > Pocket Diaries | AS12: =IFERROR(_xlfn.LET(_xlpm.v,INDEX('product-export-27-8-2026'!$A:$AJ,MATCH($A12,'product-export-27-8-2026'!$A:$A,0),MATCH(AS$1,'product-export-27-8-2026'!$1:$1,0)),IF(_xlpm.v="","",_xlpm.v)),"") -> Dorchester-Newhide-Bicolor-Pocket-Week-to-View
A13: 624 | B13: Dorchester Bicolor Pocket, Week to View, Blue- Royal Blue | C13: Diary | D13: NB-BK/RB-U-096 | E13: NB-BK/RB-U-096 | F13: NB96U | G13: Pocket | H13: Blue-Royal Blue | I13: Week to View | J13: Cream | K13: 18mm x 18mm | L13: 0.42 | M13: 9.99 | N13: 1:9.74;10:9.33;25:5.30;50:3.77;100:3.28;250:3.07;500:2.95;750:2.77;1000:2.63; | O13: =IFERROR(VALUE(_xlfn.TEXTBEFORE(_xlfn.TEXTAFTER(";"&$N13,";"&SUBSTITUTE(O$1,"Qty ","")&":"),";")),"") -> 9.74 | P13: =IFERROR(VALUE(_xlfn.TEXTBEFORE(_xlfn.TEXTAFTER(";"&$N13,";"&SUBSTITUTE(P$1,"Qty ","")&":"),";")),"") -> 9.33 | Q13: 5.3 | R13: =IFERROR(VALUE(_xlfn.TEXTBEFORE(_xlfn.TEXTAFTER(";"&$N13,";"&SUBSTITUTE(R$1,"Qty ","")&":"),";")),"") -> 3.77 | S13: =IFERROR(VALUE(_xlfn.TEXTBEFORE(_xlfn.TEXTAFTER(";"&$N13,";"&SUBSTITUTE(S$1,"Qty ","")&":"),";")),"") -> 3.28 | T13: =IFERROR(VALUE(_xlfn.TEXTBEFORE(_xlfn.TEXTAFTER(";"&$N13,";"&SUBSTITUTE(T$1,"Qty ","")&":"),";")),"") -> 3.07 | U13: =IFERROR(VALUE(_xlfn.TEXTBEFORE(_xlfn.TEXTAFTER(";"&$N13,";"&SUBSTITUTE(U$1,"Qty ","")&":"),";")),"") -> 2.95 | V13: =IFERROR(VALUE(_xlfn.TEXTBEFORE(_xlfn.TEXTAFTER(";"&$N13,";"&SUBSTITUTE(V$1,"Qty ","")&":"),";")),"") -> 2.77 | W13: =IFERROR(VALUE(_xlfn.TEXTBEFORE(_xlfn.TEXTAFTER(";"&$N13,";"&SUBSTITUTE(W$1,"Qty ","")&":"),";")),"") -> 2.63 | X13: {=IF(Y13="","",_xlfn.TEXTJOIN(";",TRUE,SUBSTITUTE($Y$1:$AG$1,"Qty ","")&":"&TEXT(Y13:AG13,"0.00"))&";")} -> 1:13.16;10:11.96;25:7.13;50:5.27;100:4.66;250:4.33;500:4.15;750:3.94;1000:3.77; | Y13: ='Blocking Prices'!$C$14+O13 -> 13.16 | Z13: ='Blocking Prices'!$D$14+P13 -> 11.96 | AA13: ='Blocking Prices'!$E$14+Q13 -> 7.13 | AB13: ='Blocking Prices'!$F$14+R13 -> 5.27 | AC13: ='Blocking Prices'!$G$14+S13 -> 4.66 | AD13: ='Blocking Prices'!$H$14+T13 -> 4.33 | AE13: ='Blocking Prices'!$I$14+U13 -> 4.15 | AF13: ='Blocking Prices'!$J$14+V13 -> 3.94 | AG13: ='Blocking Prices'!$K$14+W13 -> 3.77 | AL13: Stay organized in style with the Dorchester Bicolor Pocket Diary - Week to View. Featuring a unique bicolour design, cream paper, and a ribbon marker, it offers sophisticated weekly planning in a portable, compact size. | AN13: =IFERROR(_xlfn.LET(_xlpm.v,INDEX('product-export-27-8-2026'!$A:$AJ,MATCH($A13,'product-export-27-8-2026'!$A:$A,0),MATCH(AN$1,'product-export-27-8-2026'!$1:$1,0)),IF(_xlpm.v="","",_xlpm.v)),"") | AO13: =IFERROR(_xlfn.LET(_xlpm.v,INDEX('product-export-27-8-2026'!$A:$AJ,MATCH($A13,'product-export-27-8-2026'!$A:$A,0),MATCH(AO$1,'product-export-27-8-2026'!$1:$1,0)),IF(_xlpm.v="","",_xlpm.v)),"") | AP13: =IFERROR(_xlfn.LET(_xlpm.v,INDEX('product-export-27-8-2026'!$A:$AJ,MATCH($A13,'product-export-27-8-2026'!$A:$A,0),MATCH(AP$1,'product-export-27-8-2026'!$1:$1,0)),IF(_xlpm.v="","",_xlpm.v)),"") | AQ13: =IFERROR(_xlfn.LET(_xlpm.v,INDEX('product-export-27-8-2026'!$A:$AJ,MATCH($A13,'product-export-27-8-2026'!$A:$A,0),MATCH(AQ$1,'product-export-27-8-2026'!$1:$1,0)),IF(_xlpm.v="","",_xlpm.v)),"") | AR13: =IFERROR(_xlfn.LET(_xlpm.v,INDEX('product-export-27-8-2026'!$A:$AJ,MATCH($A13,'product-export-27-8-2026'!$A:$A,0),MATCH(AR$1,'product-export-27-8-2026'!$1:$1,0)),IF(_xlpm.v="","",_xlpm.v)),"") -> Diaries, Dorchester Collection, Diaries > Pocket Diaries | AS13: =IFERROR(_xlfn.LET(_xlpm.v,INDEX('product-export-27-8-2026'!$A:$AJ,MATCH($A13,'product-export-27-8-2026'!$A:$A,0),MATCH(AS$1,'product-export-27-8-2026'!$1:$1,0)),IF(_xlpm.v="","",_xlpm.v)),"") -> Dorchester-Newhide-Bicolor-Pocket-Week-to-View
A14: 626 | B14: Dorchester Pocket, Week to View, Aqua | C14: Diary | D14: NF-AQ-U-095 | E14: NF-AQ-U-095 | F14: NF95U | G14: Pocket | H14: Aqua | I14: Week to View | J14: White | K14: 18mm x 18mm | L14: 0.42 | M14: 8.99 | N14: 1:9.09;10:8.71;25:5.20;50:4.33;100:3.60;250:2.98;500:2.61;750:2.50;1000:2.31; | O14: =IFERROR(VALUE(_xlfn.TEXTBEFORE(_xlfn.TEXTAFTER(";"&$N14,";"&SUBSTITUTE(O$1,"Qty ","")&":"),";")),"") -> 9.09 | P14: =IFERROR(VALUE(_xlfn.TEXTBEFORE(_xlfn.TEXTAFTER(";"&$N14,";"&SUBSTITUTE(P$1,"Qty ","")&":"),";")),"") -> 8.71 | Q14: =IFERROR(VALUE(_xlfn.TEXTBEFORE(_xlfn.TEXTAFTER(";"&$N14,";"&SUBSTITUTE(Q$1,"Qty ","")&":"),";")),"") -> 5.2 | R14: =IFERROR(VALUE(_xlfn.TEXTBEFORE(_xlfn.TEXTAFTER(";"&$N14,";"&SUBSTITUTE(R$1,"Qty ","")&":"),";")),"") -> 4.33 | S14: =IFERROR(VALUE(_xlfn.TEXTBEFORE(_xlfn.TEXTAFTER(";"&$N14,";"&SUBSTITUTE(S$1,"Qty ","")&":"),";")),"") -> 3.6 | T14: =IFERROR(VALUE(_xlfn.TEXTBEFORE(_xlfn.TEXTAFTER(";"&$N14,";"&SUBSTITUTE(T$1,"Qty ","")&":"),";")),"") -> 2.98 | U14: =IFERROR(VALUE(_xlfn.TEXTBEFORE(_xlfn.TEXTAFTER(";"&$N14,";"&SUBSTITUTE(U$1,"Qty ","")&":"),";")),"") -> 2.61 | V14: =IFERROR(VALUE(_xlfn.TEXTBEFORE(_xlfn.TEXTAFTER(";"&$N14,";"&SUBSTITUTE(V$1,"Qty ","")&":"),";")),"") -> 2.5 | W14: =IFERROR(VALUE(_xlfn.TEXTBEFORE(_xlfn.TEXTAFTER(";"&$N14,";"&SUBSTITUTE(W$1,"Qty ","")&":"),";")),"") -> 2.31 | X14: {=IF(Y14="","",_xlfn.TEXTJOIN(";",TRUE,SUBSTITUTE($Y$1:$AG$1,"Qty ","")&":"&TEXT(Y14:AG14,"0.00"))&";")} -> 1:12.51;10:11.34;25:7.03;50:5.83;100:4.98;250:4.24;500:3.81;750:3.67;1000:3.45; | Y14: ='Blocking Prices'!$C$14+O14 -> 12.51 | Z14: ='Blocking Prices'!$D$14+P14 -> 11.34 | AA14: ='Blocking Prices'!$E$14+Q14 -> 7.03 | AB14: ='Blocking Prices'!$F$14+R14 -> 5.83 | AC14: ='Blocking Prices'!$G$14+S14 -> 4.98 | AD14: ='Blocking Prices'!$H$14+T14 -> 4.24 | AE14: ='Blocking Prices'!$I$14+U14 -> 3.81 | AF14: ='Blocking Prices'!$J$14+V14 -> 3.67 | AG14: ='Blocking Prices'!$K$14+W14 -> 3.45 | AL14: Organize your 2026 in style with the Dorchester Premium Pocket Diary?featuring a soft faux leather cover, recycled white paper, and a convenient Week to View layout. Eco-friendly and elegant_x000D_\n<div class="trade-info">_x000D_\n<div class="trade-info__item">_x000D_\n<div class="product-popup-modal__text rte">_x000D_\n_x000D_\n&nbsp;_x000D_\n_x000D_\n</div>_x000D_\n</div>_x000D_\n</div> | AN14: =IFERROR(_xlfn.LET(_xlpm.v,INDEX('product-export-27-8-2026'!$A:$AJ,MATCH($A14,'product-export-27-8-2026'!$A:$A,0),MATCH(AN$1,'product-export-27-8-2026'!$1:$1,0)),IF(_xlpm.v="","",_xlpm.v)),"") | AO14: =IFERROR(_xlfn.LET(_xlpm.v,INDEX('product-export-27-8-2026'!$A:$AJ,MATCH($A14,'product-export-27-8-2026'!$A:$A,0),MATCH(AO$1,'product-export-27-8-2026'!$1:$1,0)),IF(_xlpm.v="","",_xlpm.v)),"") | AP14: =IFERROR(_xlfn.LET(_xlpm.v,INDEX('product-export-27-8-2026'!$A:$AJ,MATCH($A14,'product-export-27-8-2026'!$A:$A,0),MATCH(AP$1,'product-export-27-8-2026'!$1:$1,0)),IF(_xlpm.v="","",_xlpm.v)),"") | AQ14: =IFERROR(_xlfn.LET(_xlpm.v,INDEX('product-export-27-8-2026'!$A:$AJ,MATCH($A14,'product-export-27-8-2026'!$A:$A,0),MATCH(AQ$1,'product-export-27-8-2026'!$1:$1,0)),IF(_xlpm.v="","",_xlpm.v)),"") | AR14: =IFERROR(_xlfn.LET(_xlpm.v,INDEX('product-export-27-8-2026'!$A:$AJ,MATCH($A14,'product-export-27-8-2026'!$A:$A,0),MATCH(AR$1,'product-export-27-8-2026'!$1:$1,0)),IF(_xlpm.v="","",_xlpm.v)),"") -> Diaries, Dorchester Collection, Diaries > Pocket Diaries | AS14: =IFERROR(_xlfn.LET(_xlpm.v,INDEX('product-export-27-8-2026'!$A:$AJ,MATCH($A14,'product-export-27-8-2026'!$A:$A,0),MATCH(AS$1,'product-export-27-8-2026'!$1:$1,0)),IF(_xlpm.v="","",_xlpm.v)),"") -> Dorchester-NewHide-Pocket-Week-to-View
A15: 628 | B15: Dorchester Pocket, Week to View, Black | C15: Diary | D15: NF-BK-U-095 | E15: NF-BK-U-095 | F15: NF95U | G15: Pocket | H15: Black | I15: Week to View | J15: White | K15: 18mm x 18mm | L15: 0.42 | M15: 8.99 | N15: 1:9.09;10:8.71;25:5.20;50:4.33;100:3.60;250:2.98;500:2.61;750:2.50;1000:2.31; | O15: =IFERROR(VALUE(_xlfn.TEXTBEFORE(_xlfn.TEXTAFTER(";"&$N15,";"&SUBSTITUTE(O$1,"Qty ","")&":"),";")),"") -> 9.09 | P15: =IFERROR(VALUE(_xlfn.TEXTBEFORE(_xlfn.TEXTAFTER(";"&$N15,";"&SUBSTITUTE(P$1,"Qty ","")&":"),";")),"") -> 8.71 | Q15: =IFERROR(VALUE(_xlfn.TEXTBEFORE(_xlfn.TEXTAFTER(";"&$N15,";"&SUBSTITUTE(Q$1,"Qty ","")&":"),";")),"") -> 5.2 | R15: =IFERROR(VALUE(_xlfn.TEXTBEFORE(_xlfn.TEXTAFTER(";"&$N15,";"&SUBSTITUTE(R$1,"Qty ","")&":"),";")),"") -> 4.33 | S15: =IFERROR(VALUE(_xlfn.TEXTBEFORE(_xlfn.TEXTAFTER(";"&$N15,";"&SUBSTITUTE(S$1,"Qty ","")&":"),";")),"") -> 3.6 | T15: =IFERROR(VALUE(_xlfn.TEXTBEFORE(_xlfn.TEXTAFTER(";"&$N15,";"&SUBSTITUTE(T$1,"Qty ","")&":"),";")),"") -> 2.98 | U15: =IFERROR(VALUE(_xlfn.TEXTBEFORE(_xlfn.TEXTAFTER(";"&$N15,";"&SUBSTITUTE(U$1,"Qty ","")&":"),";")),"") -> 2.61 | V15: =IFERROR(VALUE(_xlfn.TEXTBEFORE(_xlfn.TEXTAFTER(";"&$N15,";"&SUBSTITUTE(V$1,"Qty ","")&":"),";")),"") -> 2.5 | W15: =IFERROR(VALUE(_xlfn.TEXTBEFORE(_xlfn.TEXTAFTER(";"&$N15,";"&SUBSTITUTE(W$1,"Qty ","")&":"),";")),"") -> 2.31 | X15: {=IF(Y15="","",_xlfn.TEXTJOIN(";",TRUE,SUBSTITUTE($Y$1:$AG$1,"Qty ","")&":"&TEXT(Y15:AG15,"0.00"))&";")} -> 1:12.51;10:11.34;25:7.03;50:5.83;100:4.98;250:4.24;500:3.81;750:3.67;1000:3.45; | Y15: ='Blocking Prices'!$C$14+O15 -> 12.51 | Z15: ='Blocking Prices'!$D$14+P15 -> 11.34 | AA15: ='Blocking Prices'!$E$14+Q15 -> 7.03 | AB15: ='Blocking Prices'!$F$14+R15 -> 5.83 | AC15: ='Blocking Prices'!$G$14+S15 -> 4.98 | AD15: ='Blocking Prices'!$H$14+T15 -> 4.24 | AE15: ='Blocking Prices'!$I$14+U15 -> 3.81 | AF15: ='Blocking Prices'!$J$14+V15 -> 3.67 | AG15: ='Blocking Prices'!$K$14+W15 -> 3.45 | AL15: Organize your 2026 in style with the Dorchester Premium Pocket Diary?featuring a soft faux leather cover, recycled white paper, and a convenient Week to View layout. Eco-friendly and elegant | AN15: =IFERROR(_xlfn.LET(_xlpm.v,INDEX('product-export-27-8-2026'!$A:$AJ,MATCH($A15,'product-export-27-8-2026'!$A:$A,0),MATCH(AN$1,'product-export-27-8-2026'!$1:$1,0)),IF(_xlpm.v="","",_xlpm.v)),"") | AO15: =IFERROR(_xlfn.LET(_xlpm.v,INDEX('product-export-27-8-2026'!$A:$AJ,MATCH($A15,'product-export-27-8-2026'!$A:$A,0),MATCH(AO$1,'product-export-27-8-2026'!$1:$1,0)),IF(_xlpm.v="","",_xlpm.v)),"") | AP15: =IFERROR(_xlfn.LET(_xlpm.v,INDEX('product-export-27-8-2026'!$A:$AJ,MATCH($A15,'product-export-27-8-2026'!$A:$A,0),MATCH(AP$1,'product-export-27-8-2026'!$1:$1,0)),IF(_xlpm.v="","",_xlpm.v)),"") | AQ15: =IFERROR(_xlfn.LET(_xlpm.v,INDEX('product-export-27-8-2026'!$A:$AJ,MATCH($A15,'product-export-27-8-2026'!$A:$A,0),MATCH(AQ$1,'product-export-27-8-2026'!$1:$1,0)),IF(_xlpm.v="","",_xlpm.v)),"") | AR15: =IFERROR(_xlfn.LET(_xlpm.v,INDEX('product-export-27-8-2026'!$A:$AJ,MATCH($A15,'product-export-27-8-2026'!$A:$A,0),MATCH(AR$1,'product-export-27-8-2026'!$1:$1,0)),IF(_xlpm.v="","",_xlpm.v)),"") -> Diaries, Dorchester Collection, Diaries > Pocket Diaries | AS15: =IFERROR(_xlfn.LET(_xlpm.v,INDEX('product-export-27-8-2026'!$A:$AJ,MATCH($A15,'product-export-27-8-2026'!$A:$A,0),MATCH(AS$1,'product-export-27-8-2026'!$1:$1,0)),IF(_xlpm.v="","",_xlpm.v)),"") -> Dorchester-NewHide-Pocket-Week-to-View
A16: 630 | B16: Dorchester Pocket, Week to View, Blue | C16: Diary | D16: NF-BL-U-095 | E16: NF-BL-U-095 | F16: NF95U | G16: Pocket | H16: Blue | I16: Week to View | J16: White | K16: 18mm x 18mm | L16: 0.42 | M16: 8.99 | N16: 1:9.09;10:8.71;25:5.20;50:4.33;100:3.60;250:2.98;500:2.61;750:2.50;1000:2.31; | O16: =IFERROR(VALUE(_xlfn.TEXTBEFORE(_xlfn.TEXTAFTER(";"&$N16,";"&SUBSTITUTE(O$1,"Qty ","")&":"),";")),"") -> 9.09 | P16: =IFERROR(VALUE(_xlfn.TEXTBEFORE(_xlfn.TEXTAFTER(";"&$N16,";"&SUBSTITUTE(P$1,"Qty ","")&":"),";")),"") -> 8.71 | Q16: =IFERROR(VALUE(_xlfn.TEXTBEFORE(_xlfn.TEXTAFTER(";"&$N16,";"&SUBSTITUTE(Q$1,"Qty ","")&":"),";")),"") -> 5.2 | R16: =IFERROR(VALUE(_xlfn.TEXTBEFORE(_xlfn.TEXTAFTER(";"&$N16,";"&SUBSTITUTE(R$1,"Qty ","")&":"),";")),"") -> 4.33 | S16: =IFERROR(VALUE(_xlfn.TEXTBEFORE(_xlfn.TEXTAFTER(";"&$N16,";"&SUBSTITUTE(S$1,"Qty ","")&":"),";")),"") -> 3.6 | T16: =IFERROR(VALUE(_xlfn.TEXTBEFORE(_xlfn.TEXTAFTER(";"&$N16,";"&SUBSTITUTE(T$1,"Qty ","")&":"),";")),"") -> 2.98 | U16: =IFERROR(VALUE(_xlfn.TEXTBEFORE(_xlfn.TEXTAFTER(";"&$N16,";"&SUBSTITUTE(U$1,"Qty ","")&":"),";")),"") -> 2.61 | V16: =IFERROR(VALUE(_xlfn.TEXTBEFORE(_xlfn.TEXTAFTER(";"&$N16,";"&SUBSTITUTE(V$1,"Qty ","")&":"),";")),"") -> 2.5 | W16: =IFERROR(VALUE(_xlfn.TEXTBEFORE(_xlfn.TEXTAFTER(";"&$N16,";"&SUBSTITUTE(W$1,"Qty ","")&":"),";")),"") -> 2.31 | X16: {=IF(Y16="","",_xlfn.TEXTJOIN(";",TRUE,SUBSTITUTE($Y$1:$AG$1,"Qty ","")&":"&TEXT(Y16:AG16,"0.00"))&";")} -> 1:12.51;10:11.34;25:7.03;50:5.83;100:4.98;250:4.24;500:3.81;750:3.67;1000:3.45; | Y16: ='Blocking Prices'!$C$14+O16 -> 12.51 | Z16: ='Blocking Prices'!$D$14+P16 -> 11.34 | AA16: ='Blocking Prices'!$E$14+Q16 -> 7.03 | AB16: ='Blocking Prices'!$F$14+R16 -> 5.83 | AC16: ='Blocking Prices'!$G$14+S16 -> 4.98 | AD16: ='Blocking Prices'!$H$14+T16 -> 4.24 | AE16: ='Blocking Prices'!$I$14+U16 -> 3.81 | AF16: ='Blocking Prices'!$J$14+V16 -> 3.67 | AG16: ='Blocking Prices'!$K$14+W16 -> 3.45 | AL16: Organize your 2026 in style with the Dorchester Premium Pocket Diary?featuring a soft faux leather cover, recycled white paper, and a convenient Week to View layout. Eco-friendly and elegant | AN16: =IFERROR(_xlfn.LET(_xlpm.v,INDEX('product-export-27-8-2026'!$A:$AJ,MATCH($A16,'product-export-27-8-2026'!$A:$A,0),MATCH(AN$1,'product-export-27-8-2026'!$1:$1,0)),IF(_xlpm.v="","",_xlpm.v)),"") | AO16: =IFERROR(_xlfn.LET(_xlpm.v,INDEX('product-export-27-8-2026'!$A:$AJ,MATCH($A16,'product-export-27-8-2026'!$A:$A,0),MATCH(AO$1,'product-export-27-8-2026'!$1:$1,0)),IF(_xlpm.v="","",_xlpm.v)),"") | AP16: =IFERROR(_xlfn.LET(_xlpm.v,INDEX('product-export-27-8-2026'!$A:$AJ,MATCH($A16,'product-export-27-8-2026'!$A:$A,0),MATCH(AP$1,'product-export-27-8-2026'!$1:$1,0)),IF(_xlpm.v="","",_xlpm.v)),"") | AQ16: =IFERROR(_xlfn.LET(_xlpm.v,INDEX('product-export-27-8-2026'!$A:$AJ,MATCH($A16,'product-export-27-8-2026'!$A:$A,0),MATCH(AQ$1,'product-export-27-8-2026'!$1:$1,0)),IF(_xlpm.v="","",_xlpm.v)),"") | AR16: =IFERROR(_xlfn.LET(_xlpm.v,INDEX('product-export-27-8-2026'!$A:$AJ,MATCH($A16,'product-export-27-8-2026'!$A:$A,0),MATCH(AR$1,'product-export-27-8-2026'!$1:$1,0)),IF(_xlpm.v="","",_xlpm.v)),"") -> Diaries, Dorchester Collection, Diaries > Pocket Diaries | AS16: =IFERROR(_xlfn.LET(_xlpm.v,INDEX('product-export-27-8-2026'!$A:$AJ,MATCH($A16,'product-export-27-8-2026'!$A:$A,0),MATCH(AS$1,'product-export-27-8-2026'!$1:$1,0)),IF(_xlpm.v="","",_xlpm.v)),"") -> Dorchester-NewHide-Pocket-Week-to-View
A17: 632 | B17: Dorchester Pocket, Week to View, Burgundy | C17: Diary | D17: NF-BG-U-095 | E17: NF-BG-U-095 | F17: NF95U | G17: Pocket | H17: Burgundy | I17: Week to View | J17: White | K17: 18mm x 18mm | L17: 0.42 | M17: 8.99 | N17: 1:9.09;10:8.71;25:5.20;50:4.33;100:3.60;250:2.98;500:2.61;750:2.50;1000:2.31; | O17: =IFERROR(VALUE(_xlfn.TEXTBEFORE(_xlfn.TEXTAFTER(";"&$N17,";"&SUBSTITUTE(O$1,"Qty ","")&":"),";")),"") -> 9.09 | P17: =IFERROR(VALUE(_xlfn.TEXTBEFORE(_xlfn.TEXTAFTER(";"&$N17,";"&SUBSTITUTE(P$1,"Qty ","")&":"),";")),"") -> 8.71 | Q17: =IFERROR(VALUE(_xlfn.TEXTBEFORE(_xlfn.TEXTAFTER(";"&$N17,";"&SUBSTITUTE(Q$1,"Qty ","")&":"),";")),"") -> 5.2 | R17: =IFERROR(VALUE(_xlfn.TEXTBEFORE(_xlfn.TEXTAFTER(";"&$N17,";"&SUBSTITUTE(R$1,"Qty ","")&":"),";")),"") -> 4.33 | S17: =IFERROR(VALUE(_xlfn.TEXTBEFORE(_xlfn.TEXTAFTER(";"&$N17,";"&SUBSTITUTE(S$1,"Qty ","")&":"),";")),"") -> 3.6 | T17: =IFERROR(VALUE(_xlfn.TEXTBEFORE(_xlfn.TEXTAFTER(";"&$N17,";"&SUBSTITUTE(T$1,"Qty ","")&":"),";")),"") -> 2.98 | U17: =IFERROR(VALUE(_xlfn.TEXTBEFORE(_xlfn.TEXTAFTER(";"&$N17,";"&SUBSTITUTE(U$1,"Qty ","")&":"),";")),"") -> 2.61 | V17: =IFERROR(VALUE(_xlfn.TEXTBEFORE(_xlfn.TEXTAFTER(";"&$N17,";"&SUBSTITUTE(V$1,"Qty ","")&":"),";")),"") -> 2.5 | W17: =IFERROR(VALUE(_xlfn.TEXTBEFORE(_xlfn.TEXTAFTER(";"&$N17,";"&SUBSTITUTE(W$1,"Qty ","")&":"),";")),"") -> 2.31 | X17: {=IF(Y17="","",_xlfn.TEXTJOIN(";",TRUE,SUBSTITUTE($Y$1:$AG$1,"Qty ","")&":"&TEXT(Y17:AG17,"0.00"))&";")} -> 1:12.51;10:11.34;25:7.03;50:5.83;100:4.98;250:4.24;500:3.81;750:3.67;1000:3.45; | Y17: ='Blocking Prices'!$C$14+O17 -> 12.51 | Z17: ='Blocking Prices'!$D$14+P17 -> 11.34 | AA17: ='Blocking Prices'!$E$14+Q17 -> 7.03 | AB17: ='Blocking Prices'!$F$14+R17 -> 5.83 | AC17: ='Blocking Prices'!$G$14+S17 -> 4.98 | AD17: ='Blocking Prices'!$H$14+T17 -> 4.24 | AE17: ='Blocking Prices'!$I$14+U17 -> 3.81 | AF17: ='Blocking Prices'!$J$14+V17 -> 3.67 | AG17: ='Blocking Prices'!$K$14+W17 -> 3.45 | AL17: Organize your 2026 in style with the Dorchester Premium Pocket Diary?featuring a soft faux leather cover, recycled white paper, and a convenient Week to View layout. Eco-friendly and elegant_x000D_\n<div class="trade-info">_x000D_\n<div class="trade-info__item">_x000D_\n<div class="product-popup-modal__text rte">_x000D_\n_x000D_\n&nbsp;_x000D_\n_x000D_\n</div>_x000D_\n</div>_x000D_\n</div> | AN17: =IFERROR(_xlfn.LET(_xlpm.v,INDEX('product-export-27-8-2026'!$A:$AJ,MATCH($A17,'product-export-27-8-2026'!$A:$A,0),MATCH(AN$1,'product-export-27-8-2026'!$1:$1,0)),IF(_xlpm.v="","",_xlpm.v)),"") | AO17: =IFERROR(_xlfn.LET(_xlpm.v,INDEX('product-export-27-8-2026'!$A:$AJ,MATCH($A17,'product-export-27-8-2026'!$A:$A,0),MATCH(AO$1,'product-export-27-8-2026'!$1:$1,0)),IF(_xlpm.v="","",_xlpm.v)),"") | AP17: =IFERROR(_xlfn.LET(_xlpm.v,INDEX('product-export-27-8-2026'!$A:$AJ,MATCH($A17,'product-export-27-8-2026'!$A:$A,0),MATCH(AP$1,'product-export-27-8-2026'!$1:$1,0)),IF(_xlpm.v="","",_xlpm.v)),"") | AQ17: =IFERROR(_xlfn.LET(_xlpm.v,INDEX('product-export-27-8-2026'!$A:$AJ,MATCH($A17,'product-export-27-8-2026'!$A:$A,0),MATCH(AQ$1,'product-export-27-8-2026'!$1:$1,0)),IF(_xlpm.v="","",_xlpm.v)),"") | AR17: =IFERROR(_xlfn.LET(_xlpm.v,INDEX('product-export-27-8-2026'!$A:$AJ,MATCH($A17,'product-export-27-8-2026'!$A:$A,0),MATCH(AR$1,'product-export-27-8-2026'!$1:$1,0)),IF(_xlpm.v="","",_xlpm.v)),"") -> Diaries, Dorchester Collection, Diaries > Pocket Diaries | AS17: =IFERROR(_xlfn.LET(_xlpm.v,INDEX('product-export-27-8-2026'!$A:$AJ,MATCH($A17,'product-export-27-8-2026'!$A:$A,0),MATCH(AS$1,'product-export-27-8-2026'!$1:$1,0)),IF(_xlpm.v="","",_xlpm.v)),"") -> Dorchester-NewHide-Pocket-Week-to-View
